Workbook
Name a: List!$A$2:$A$13
Name AdjustmentTypes: List!$L$2:$L$6
Name BudgetCategoryList: List!$I$2:$I$14
Name CashierList: List!$G$2:$G$4
Name CashierLists: List!$G$2:$G$6
Name CategoryList: List!$A$2:$A$13
Name CategoryLists: List!$A$2:$A$17
Name DateList: List!$J$2:$J$32
Name ddmmyyyy: Table8[Date]
Name ECategoryList: List!$F$2:$F$8
Name EPMethod: List!$H$2:$H$3
Name ExpensesCategoryList: List!$F$2:$F$14
Name PaymentMethodList: List!$H$2:$H$5
Name ProductID: List!$K$2:$K$51
Name ProductList: List!$B$2:$B$12
Name ProductNames: List!$B$2:$B$78
Name Statuslist: List!$E$2:$E$3
Name SupplierList: List!$D$2:$D$6
Name UnitofMeasures: List!$C$2:$C$19
Name Uomlist: List!$C$2:$C$18

Sheet User Guide
A1: Sales & Inventory Management System (SIMS PRO) V2.0
A4: Developed by :
A6: Olamilekan Analytics.
A8: Project Overview
A9: This sales & Inventory Management System was developed in Microsoft Excel to help businesses manage products, purchases, sales, inventory, expenses, budgeting and business performance through an interactive
A10: dashboard.
A12: FEATURES
A13: Product Management
A14: Stock Purchase Management
A15: Daily Sales Tracking
A16: Inventory Management
A17: Stock Adjustment
... A86: All Rights Reserved.

Sheet Dashboard
A1: SIMS PRO - Sales & Inventory Management System
B3: Total Products | D3: Total Sales | F3: Total Purchases | H3: Inventory Value | J3: Low Stock Items | L3: Out Of Stock Items
N4: Total Expenses | P4: Net Profit | R4: Total Transactions Today | T4: QTY Sold Today | V4: Revenue Today | X4: Profit Today | Z4: Today Sales | AB4: Yesterday's Sales | AD4: This week's Sales | AF4: This Month's Sales | AH4: Today's Profit | AJ4: Gross Profit | AL4: Net Profit
B5: =COUNTIF('Product Master'!A:A,"P*")-1 -> 15 | D5: =SUM('Daily Sales Entry'!J:J) -> 284700 | F5: =SUM('Stock Purchase'!H:H) -> 1995000 | H5: =SUM(Inventory!Q:Q) -> 1813300 | J5: =COUNTIF(Inventory!R:R,"Low Stock") -> 0 | L5: =COUNTIF(Inventory!R:R,"Out of Stock") -> 0 | N5: =SUM(Expenses!E:E) -> 42500 | P5: =D5-N5 -> 242200 | R5: =SUMPRODUCT(('Daily Sales Entry'!$A$2:$A$1000=TODAY())*('Daily Sales Entry'!$G$2:$G$1000>0)) -> 0 | T5: =SUMIFS('Daily Sales Entry'!G:G,'Daily Sales Entry'!A:A,TODAY()) -> 0 | V5: =SUMIF('Daily Sales Entry'!A:A,TODAY(),'Daily Sales Entry'!L:L) -> 0 | X5: =SUMIF('Daily Sales Entry'!A:A,TODAY(),'Daily Sales Entry'!M:M) -> 0 | Z5: =SUMIFS('Daily Sales Entry'!J:J,'Daily Sales Entry'!A:A,TODAY()) -> 0 | AB5: =SUMIFS('Daily Sales Entry'!J:J,'Daily Sales Entry'!A:A,TODAY()-1) -> 0 | AD5: =SUMIFS('Daily Sales Entry'!J:J,'Daily Sales Entry'!A:A,">="&TODAY()-WEEKDAY(TODAY(),2)+1,'Daily Sales Entry'!A:A,"<"&TODAY()+1) -> 30000 | AF5: =SUMIFS('Daily Sales Entry'!J:J,'Daily Sales Entry'!A:A,">="&EOMONTH(TODAY(),-1)+1,'Daily Sales Entry'!A:A,"<"&EOMONTH(TODAY(),0)+1) -> 0 | AH5: =SUMIFS('Daily Sales Entry'!M:M,'Daily Sales Entry'!A:A,TODAY()) -> 0 | AJ5: =SUM('Daily Sales Entry'!M:M) -> 80300 | AL5: =AJ5-N5 -> 37800
AJ7: Gross Profit Margin | AL7: Net Profit Margin
AJ8: =IFERROR(AJ5/D5,0) -> 0.28205128 | AL8: =IFERROR(AL5/D5,0) -> 0.13277134
B10: Product Name | C10: Total Sold | R10: Status | S10: Count | V10: Date | W10: Day | X10: Sales
B11: Shaki | C11: =SUMIF('Daily Sales Entry'!$D:$D,B11,'Daily Sales Entry'!$G:$G) -> 27 | R11: In Stock | S11: =COUNTIF(Inventory!R:R,"In Stock") -> 15 | V11: =TODAY()-6 -> 46261 | W11: =TEXT(V11,"ddd") -> Thu | X11: =SUMIFS('Daily Sales Entry'!J:J,'Daily Sales Entry'!A:A,V11) -> 0
B12: Moin Moin | C12: =SUMIF('Daily Sales Entry'!$D:$D,B12,'Daily Sales Entry'!$G:$G) -> 19 | R12: Low Stock | S12: =COUNTIF(Inventory!R:R,"Low Stock") -> 0 | V12: =V11+1 -> 46262 | W12: =TEXT(V12,"ddd") -> Fri | X12: =SUMIFS('Daily Sales Entry'!J:J,'Daily Sales Entry'!A:A,V12) -> 0
B13: Beef | C13: =SUMIF('Daily Sales Entry'!$D:$D,B13,'Daily Sales Entry'!$G:$G) -> 16 | R13: Out of Stock | S13: =COUNTIF(Inventory!R:R,"Out of Stock") -> 0 | V13: =V12+1 -> 46263 | W13: =TEXT(V13,"ddd") -> Sat | X13: =SUMIFS('Daily Sales Entry'!J:J,'Daily Sales Entry'!A:A,V13) -> 0
B14: Cow leg | C14: =SUMIF('Daily Sales Entry'!$D:$D,B14,'Daily Sales Entry'!$G:$G) -> 8 | V14: =V13+1 -> 46264 | W14: =TEXT(V14,"ddd") -> Sun | X14: =SUMIFS('Daily Sales Entry'!J:J,'Daily Sales Entry'!A:A,V14) -> 0
B15: Semovita | C15: =SUMIF('Daily Sales Entry'!$D:$D,B15,'Daily Sales Entry'!$G:$G) -> 7 | V15: =V14+1 -> 46265 | W15: =TEXT(V15,"ddd") -> Mon | X15: =SUMIFS('Daily Sales Entry'!J:J,'Daily Sales Entry'!A:A,V15) -> 30000
B16: Chicken Pie | C16: =SUMIF('Daily Sales Entry'!$D:$D,B16,'Daily Sales Entry'!$G:$G) -> 7 | V16: =V15+1 -> 46266 | W16: =TEXT(V16,"ddd") -> Tue | X16: =SUMIFS('Daily Sales Entry'!J:J,'Daily Sales Entry'!A:A,V16) -> 0
B17: Eva Water 0.75Cl | C17: =SUMIF('Daily Sales Entry'!$D:$D,B17,'Daily Sales Entry'!$G:$G) -> 7 | V17: =V16+1 -> 46267 | W17: =TEXT(V17,"ddd") -> Wed | X17: =SUMIFS('Daily Sales Entry'!J:J,'Daily Sales Entry'!A:A,V17) -> 0
B18: Beef Roll | C18: =SUMIF('Daily Sales Entry'!$D:$D,B18,'Daily Sales Entry'!$G:$G) -> 5
B19: Pet Lucozade Boost | C19: =SUMIF('Daily Sales Entry'!$D:$D,B19,'Daily Sales Entry'!$G:$G) -> 5
B20: Eba | C20: =SUMIF('Daily Sales Entry'!$D:$D,B20,'Daily Sales Entry'!$G:$G) -> 3
B21: Meat Pie | C21: =SUMIF('Daily Sales Entry'!$D:$D,B21,'Daily Sales Entry'!$G:$G) -> 3
B22: Ofada Rice New | C22: =SUMIF('Daily Sales Entry'!$D:$D,B22,'Daily Sales Entry'!$G:$G) -> 0 | J22: RECENT SALES | N22: LOW STOCK ALERT
B23: Tanta Roll | C23: =SUMIF('Daily Sales Entry'!$D:$D,B23,'Daily Sales Entry'!$G:$G) -> 0 | I23: Sales ID | J23: Product | K23: QTY | L23: Amount | N23: Product Name | O23: Current Stock | P23: Reorder Level | Q23: Status | S23: Category | T23: Total Sales
B24: Doughnut | C24: =SUMIF('Daily Sales Entry'!$D:$D,B24,'Daily Sales Entry'!$G:$G) -> 0 | I24: ='Daily Sales Entry'!B10 -> 4 | J24: ='Daily Sales Entry'!D10 -> Shaki | K24: ='Daily Sales Entry'!G10 -> 15 | L24: ='Daily Sales Entry'!J10 -> 18000 | N24: Shaki | O24: =IF(N24="","",IFERROR(VLOOKUP(N24,Inventory!$B:$R,12,FALSE),0)) -> 21 | P24: =IF(N24="","",IFERROR(VLOOKUP(N24,Inventory!$B:$R,15,FALSE),0)) -> 20 | Q24: =IF(N24="","",IFERROR(IF(O24=0,"Out of Stock",IF(O24<=P24,"Low Stock","In Stock")),"Out of Stock")) -> In Stock | S24: Food | T24: =SUMIF('Daily Sales Entry'!$E:$E,S24,'Daily Sales Entry'!$G:$G) -> 80
B25: Beef Burger | C25: =SUMIF('Daily Sales Entry'!$D:$D,B25,'Daily Sales Entry'!$G:$G) -> 0 | I25: ='Daily Sales Entry'!B11 -> 4 | J25: ='Daily Sales Entry'!D11 -> Moin Moin | K25: ='Daily Sales Entry'!G11 -> 13 | L25: ='Daily Sales Entry'!J11 -> 10400 | N25: Beef | O25: =IF(N25="","",IFERROR(VLOOKUP(N25,Inventory!$B:$R,12,FALSE),0)) -> 69 | P25: =IF(N25="","",IFERROR(VLOOKUP(N25,Inventory!$B:$R,15,FALSE),0)) -> 20 | Q25: =IF(N25="","",IFERROR(IF(O25=0,"Out of Stock",IF(O25<=P25,"Low Stock","In Stock")),"Out of Stock")) -> In Stock | S25: Snacks | T25: =SUMIF('Daily Sales Entry'!$E:$E,S25,'Daily Sales Entry'!$G:$G) -> 20
B26: Scotch Egg | C26: =SUMIF('Daily Sales Entry'!$D:$D,B26,'Daily Sales Entry'!$G:$G) -> 0 | I26: ='Daily Sales Entry'!B5 -> 1 | J26: ='Daily Sales Entry'!D5 -> Semovita | K26: ='Daily Sales Entry'!G5 -> 7 | L26: ='Daily Sales Entry'!J5 -> 4900 | N26: Semovita | O26: =IF(N26="","",IFERROR(VLOOKUP(N26,Inventory!$B:$R,12,FALSE),0)) -> 43 | P26: =IF(N26="","",IFERROR(VLOOKUP(N26,Inventory!$B:$R,15,FALSE),0)) -> 20 | Q26: =IF(N26="","",IFERROR(IF(O26=0,"Out of Stock",IF(O26<=P26,"Low Stock","In Stock")),"Out of Stock")) -> In Stock | S26: Drinks | T26: =SUMIF('Daily Sales Entry'!$E:$E,S26,'Daily Sales Entry'!$G:$G) -> 27
B27: Ppg Chicken | C27: =SUMIF('Daily Sales Entry'!$D:$D,B27,'Daily Sales Entry'!$G:$G) -> 0 | I27: ='Daily Sales Entry'!B7 -> 1 | J27: ='Daily Sales Entry'!D7 -> Moin Moin | K27: ='Daily Sales Entry'!G7 -> 6 | L27: ='Daily Sales Entry'!J7 -> 4800 | N27: Cow leg | O27: =IF(N27="","",IFERROR(VLOOKUP(N27,Inventory!$B:$R,12,FALSE),0)) -> 42 | P27: =IF(N27="","",IFERROR(VLOOKUP(N27,Inventory!$B:$R,15,FALSE),0)) -> 20 | Q27: =IF(N27="","",IFERROR(IF(O27=0,"Out of Stock",IF(O27<=P27,"Low Stock","In Stock")),"Out of Stock")) -> In Stock | S27: Beverages | T27: =SUMIF('Daily Sales Entry'!$E:$E,S27,'Daily Sales Entry'!$G:$G) -> 0
B28: Roasted Chicken | C28: =SUMIF('Daily Sales Entry'!$D:$D,B28,'Daily Sales Entry'!$G:$G) -> 0 | I28: ='Daily Sales Entry'!B9 -> 3 | J28: ='Daily Sales Entry'!D9 -> Beef | K28: ='Daily Sales Entry'!G9 -> 6 | L28: ='Daily Sales Entry'!J9 -> 6000 | N28: Eba | O28: =IF(N28="","",IFERROR(VLOOKUP(N28,Inventory!$B:$R,12,FALSE),0)) -> 47 | P28: =IF(N28="","",IFERROR(VLOOKUP(N28,Inventory!$B:$R,15,FALSE),0)) -> 20 | Q28: =IF(N28="","",IFERROR(IF(O28=0,"Out of Stock",IF(O28<=P28,"Low Stock","In Stock")),"Out of Stock")) -> In Stock | S28: Clothing | T28: =SUMIF('Daily Sales Entry'!$E:$E,S28,'Daily Sales Entry'!$G:$G) -> 0
B29: Chicken Salad | C29: =SUMIF('Daily Sales Entry'!$D:$D,B29,'Daily Sales Entry'!$G:$G) -> 0 | I29: ='Daily Sales Entry'!B2 -> 1 | J29: ='Daily Sales Entry'!D2 -> Beef | K29: ='Daily Sales Entry'!G2 -> 5 | L29: ='Daily Sales Entry'!J2 -> 5000 | N29: Moin Moin | O29: =IF(N29="","",IFERROR(VLOOKUP(N29,Inventory!$B:$R,12,FALSE),0)) -> 31 | P29: =IF(N29="","",IFERROR(VLOOKUP(N29,Inventory!$B:$R,15,FALSE),0)) -> 20 | Q29: =IF(N29="","",IFERROR(IF(O29=0,"Out of Stock",IF(O29<=P29,"Low Stock","In Stock")),"Out of Stock")) -> In Stock | S29: Cosmetics | T29: =SUMIF('Daily Sales Entry'!$E:$E,S29,'Daily Sales Entry'!$G:$G) -> 0
B30: Vegetable Salad | C30: =SUMIF('Daily Sales Entry'!$D:$D,B30,'Daily Sales Entry'!$G:$G) -> 0 | I30: ='Daily Sales Entry'!B3 -> 1 | J30: ='Daily Sales Entry'!D3 -> Shaki | K30: ='Daily Sales Entry'!G3 -> 4 | L30: ='Daily Sales Entry'!J3 -> 4800 | N30: Salad Pack | O30: =IF(N30="","",IFERROR(VLOOKUP(N30,Inventory!$B:$R,12,FALSE),0)) -> 0 | P30: =IF(N30="","",IFERROR(VLOOKUP(N30,Inventory!$B:$R,15,FALSE),0)) -> 0 | Q30: =IF(N30="","",IFERROR(IF(O30=0,"Out of Stock",IF(O30<=P30,"Low Stock","In Stock")),"Out of Stock")) -> Out of Stock | S30: Electronics | T30: =SUMIF('Daily Sales Entry'!$E:$E,S30,'Daily Sales Entry'!$G:$G) -> 0
B31: Scramble Egg | C31: =SUMIF('Daily Sales Entry'!$D:$D,B31,'Daily Sales Entry'!$G:$G) -> 0 | I31: ='Daily Sales Entry'!B4 -> 1 | J31: ='Daily Sales Entry'!D4 -> Cow leg | K31: ='Daily Sales Entry'!G4 -> 4 | L31: ='Daily Sales Entry'!J4 -> 6000 | N31: Schweppes Can 33Cl | O31: =IF(N31="","",IFERROR(VLOOKUP(N31,Inventory!$B:$R,12,FALSE),0)) -> 0 | P31: =IF(N31="","",IFERROR(VLOOKUP(N31,Inventory!$B:$R,15,FALSE),0)) -> 0 | Q31: =IF(N31="","",IFERROR(IF(O31=0,"Out of Stock",IF(O31<=P31,"Low Stock","In Stock")),"Out of Stock")) -> Out of Stock | S31: Frozen Foods | T31: =SUMIF('Daily Sales Entry'!$E:$E,S31,'Daily Sales Entry'!$G:$G) -> 0
B32: Cup Cake | C32: =SUMIF('Daily Sales Entry'!$D:$D,B32,'Daily Sales Entry'!$G:$G) -> 0 | I32: ='Daily Sales Entry'!B8 -> 2 | J32: ='Daily Sales Entry'!D8 -> Cow leg | K32: ='Daily Sales Entry'!G8 -> 4 | L32: ='Daily Sales Entry'!J8 -> 6000 | N32: Coke Pet Light 50cl | O32: =IF(N32="","",IFERROR(VLOOKUP(N32,Inventory!$B:$R,12,FALSE),0)) -> 0 | P32: =IF(N32="","",IFERROR(VLOOKUP(N32,Inventory!$B:$R,15,FALSE),0)) -> 0 | Q32: =IF(N32="","",IFERROR(IF(O32=0,"Out of Stock",IF(O32<=P32,"Low Stock","In Stock")),"Out of Stock")) -> Out of Stock | S32: Furniture | T32: =SUMIF('Daily Sales Entry'!$E:$E,S32,'Daily Sales Entry'!$G:$G) -> 0
B33: Fruit Cake | C33: =SUMIF('Daily Sales Entry'!$D:$D,B33,'Daily Sales Entry'!$G:$G) -> 0 | I33: ='Daily Sales Entry'!B6 -> 1 | J33: ='Daily Sales Entry'!D6 -> Eba | K33: ='Daily Sales Entry'!G6 -> 3 | L33: ='Daily Sales Entry'!J6 -> 1500 | N33: Teem Lemon Pet | O33: =IF(N33="","",IFERROR(VLOOKUP(N33,Inventory!$B:$R,12,FALSE),0)) -> 0 | P33: =IF(N33="","",IFERROR(VLOOKUP(N33,Inventory!$B:$R,15,FALSE),0)) -> 0 | Q33: =IF(N33="","",IFERROR(IF(O33=0,"Out of Stock",IF(O33<=P33,"Low Stock","In Stock")),"Out of Stock")) -> Out of Stock | S33: Groceries | T33: =SUMIF('Daily Sales Entry'!$E:$E,S33,'Daily Sales Entry'!$G:$G) -> 0
B34: 10 CELEBRATION CAKE | C34: =SUMIF('Daily Sales Entry'!$D:$D,B34,'Daily Sales Entry'!$G:$G) -> 0 | I34: ='Daily Sales Entry'!B12 -> 5 | J34: ='Daily Sales Entry'!D12 -> Meat Pie | K34: ='Daily Sales Entry'!G12 -> 3 | L34: ='Daily Sales Entry'!J12 -> 2700 | N34: FAB Energy Drinks | O34: =IF(N34="","",IFERROR(VLOOKUP(N34,Inventory!$B:$R,12,FALSE),0)) -> 45 | P34: =IF(N34="","",IFERROR(VLOOKUP(N34,Inventory!$B:$R,15,FALSE),0)) -> 20 | Q34: =IF(N34="","",IFERROR(IF(O34=0,"Out of Stock",IF(O34<=P34,"Low Stock","In Stock")),"Out of Stock")) -> In Stock | S34: Office Supplies | T34: =SUMIF('Daily Sales Entry'!$E:$E,S34,'Daily Sales Entry'!$G:$G) -> 0
B35: 8 CELEBRATION CAKE | C35: =SUMIF('Daily Sales Entry'!$D:$D,B35,'Daily Sales Entry'!$G:$G) -> 0 | I35: ='Daily Sales Entry'!B13 -> 5 | J35: ='Daily Sales Entry'!D13 -> Chicken Pie | K35: ='Daily Sales Entry'!G13 -> 7 | L35: ='Daily Sales Entry'!J13 -> 7000 | N35: Lucozade Sport Pet 50cl | O35: =IF(N35="","",IFERROR(VLOOKUP(N35,Inventory!$B:$R,12,FALSE),0)) -> 45 | P35: =IF(N35="","",IFERROR(VLOOKUP(N35,Inventory!$B:$R,15,FALSE),0)) -> 20 | Q35: =IF(N35="","",IFERROR(IF(O35=0,"Out of Stock",IF(O35<=P35,"Low Stock","In Stock")),"Out of Stock")) -> In Stock | S35: Pharmaceuticals | T35: =SUMIF('Daily Sales Entry'!$E:$E,S35,'Daily Sales Entry'!$G:$G) -> 0
B36: 6 CELEBRATION CAKE | C36: =SUMIF('Daily Sales Entry'!$D:$D,B36,'Daily Sales Entry'!$G:$G) -> 0 | I36: ='Daily Sales Entry'!B14 -> 5 | J36: ='Daily Sales Entry'!D14 -> Beef Roll | K36: ='Daily Sales Entry'!G14 -> 5 | L36: ='Daily Sales Entry'!J14 -> 3500 | N36: Pet Lucozade Boost | O36: =IF(N36="","",IFERROR(VLOOKUP(N36,Inventory!$B:$R,12,FALSE),0)) -> 65 | P36: =IF(N36="","",IFERROR(VLOOKUP(N36,Inventory!$B:$R,15,FALSE),0)) -> 10 | Q36: =IF(N36="","",IFERROR(IF(O36=0,"Out of Stock",IF(O36<=P36,"Low Stock","In Stock")),"Out of Stock")) -> In Stock | S36: Stationery | T36: =SUMIF('Daily Sales Entry'!$E:$E,S36,'Daily Sales Entry'!$G:$G) -> 0
B37: MoinMoin Elewe | C37: =SUMIF('Daily Sales Entry'!$D:$D,B37,'Daily Sales Entry'!$G:$G) -> 0 | I37: ='Daily Sales Entry'!B15 -> 6 | J37: ='Daily Sales Entry'!D15 -> Pet Lucozade Boost | K37: ='Daily Sales Entry'!G15 -> 5 | L37: ='Daily Sales Entry'!J15 -> 100000 | N37: Eva Water 0.75Cl | O37: =IF(N37="","",IFERROR(VLOOKUP(N37,Inventory!$B:$R,12,FALSE),0)) -> 63 | P37: =IF(N37="","",IFERROR(VLOOKUP(N37,Inventory!$B:$R,15,FALSE),0)) -> 10 | Q37: =IF(N37="","",IFERROR(IF(O37=0,"Out of Stock",IF(O37<=P37,"Low Stock","In Stock")),"Out of Stock")) -> In Stock | S37: Household items | T37: =SUMIF('Daily Sales Entry'!$E:$E,S37,'Daily Sales Entry'!$G:$G) -> 0
B38: Sunshine Loaf-Sliced | C38: =SUMIF('Daily Sales Entry'!$D:$D,B38,'Daily Sales Entry'!$G:$G) -> 0 | I38: ='Daily Sales Entry'!B16 -> 6 | J38: ='Daily Sales Entry'!D16 -> Eva Water 0.75Cl | K38: ='Daily Sales Entry'!G16 -> 7 | L38: ='Daily Sales Entry'!J16 -> 59500 | N38: Ponmo | O38: =IF(N38="","",IFERROR(VLOOKUP(N38,Inventory!$B:$R,12,FALSE),0)) -> 0 | P38: =IF(N38="","",IFERROR(VLOOKUP(N38,Inventory!$B:$R,15,FALSE),0)) -> 0 | Q38: =IF(N38="","",IFERROR(IF(O38=0,"Out of Stock",IF(O38<=P38,"Low Stock","In Stock")),"Out of Stock")) -> Out of Stock | S38: Cakes | T38: =SUMIF('Daily Sales Entry'!$E:$E,S38,'Daily Sales Entry'!$G:$G) -> 0
B39: Fruit Bread Loaf | C39: =SUMIF('Daily Sales Entry'!$D:$D,B39,'Daily Sales Entry'!$G:$G) -> 0 | I39: ='Daily Sales Entry'!B17 -> 6 | J39: ='Daily Sales Entry'!D17 -> Beef | K39: ='Daily Sales Entry'!G17 -> 5 | L39: ='Daily Sales Entry'!J17 -> 5000 | N39: Meat Pie | O39: =IF(N39="","",IFERROR(VLOOKUP(N39,Inventory!$B:$R,12,FALSE),0)) -> 47 | P39: =IF(N39="","",IFERROR(VLOOKUP(N39,Inventory!$B:$R,15,FALSE),0)) -> 20 | Q39: =IF(N39="","",IFERROR(IF(O39=0,"Out of Stock",IF(O39<=P39,"Low Stock","In Stock")),"Out of Stock")) -> In Stock | S39: Soup | T39: =SUMIF('Daily Sales Entry'!$E:$E,S39,'Daily Sales Entry'!$G:$G) -> 0
B40: Efo-Riro Soup 2 | C40: =SUMIF('Daily Sales Entry'!$D:$D,B40,'Daily Sales Entry'!$G:$G) -> 0 | I40: ='Daily Sales Entry'!B18 -> 6 | J40: ='Daily Sales Entry'!D18 -> Shaki | K40: ='Daily Sales Entry'!G18 -> 8 | L40: ='Daily Sales Entry'!J18 -> 9600 | N40: Chicken Pie | O40: =IF(N40="","",IFERROR(VLOOKUP(N40,Inventory!$B:$R,12,FALSE),0)) -> 43 | P40: =IF(N40="","",IFERROR(VLOOKUP(N40,Inventory!$B:$R,15,FALSE),0)) -> 20 | Q40: =IF(N40="","",IFERROR(IF(O40=0,"Out of Stock",IF(O40<=P40,"Low Stock","In Stock")),"Out of Stock")) -> In Stock
B41: Egusi Soup 2 | C41: =SUMIF('Daily Sales Entry'!$D:$D,B41,'Daily Sales Entry'!$G:$G) -> 0 | I41: ='Daily Sales Entry'!B19 -> 7 | J41: ='Daily Sales Entry'!D19 -> Lucozade Sport Pet 50cl | K41: ='Daily Sales Entry'!G19 -> 5 | L41: ='Daily Sales Entry'!J19 -> 7500 | N41: Beef Roll | O41: =IF(N41="","",IFERROR(VLOOKUP(N41,Inventory!$B:$R,12,FALSE),0)) -> 45 | P41: =IF(N41="","",IFERROR(VLOOKUP(N41,Inventory!$B:$R,15,FALSE),0)) -> 20 | Q41: =IF(N41="","",IFERROR(IF(O41=0,"Out of Stock",IF(O41<=P41,"Low Stock","In Stock")),"Out of Stock")) -> In Stock
B42: Tantis Fish Ola | C42: =SUMIF('Daily Sales Entry'!$D:$D,B42,'Daily Sales Entry'!$G:$G) -> 0 | I42: ='Daily Sales Entry'!B20 -> 7 | J42: ='Daily Sales Entry'!D20 -> FAB Energy Drinks | K42: ='Daily Sales Entry'!G20 -> 5 | L42: ='Daily Sales Entry'!J20 -> 7500 | N42: Tanta Roll | O42: =IF(N42="","",IFERROR(VLOOKUP(N42,Inventory!$B:$R,12,FALSE),0)) -> 0 | P42: =IF(N42="","",IFERROR(VLOOKUP(N42,Inventory!$B:$R,15,FALSE),0)) -> 0 | Q42: =IF(N42="","",IFERROR(IF(O42=0,"Out of Stock",IF(O42<=P42,"Low Stock","In Stock")),"Out of Stock")) -> Out of Stock
B43: Ponmo | C43: =SUMIF('Daily Sales Entry'!$D:$D,B43,'Daily Sales Entry'!$G:$G) -> 0 | I43: ='Daily Sales Entry'!B21 -> 7 | J43: ='Daily Sales Entry'!D21 -> Chin Chin 224 gms | K43: ='Daily Sales Entry'!G21 -> 5 | L43: ='Daily Sales Entry'!J21 -> 7500 | N43: Doughnut | O43: =IF(N43="","",IFERROR(VLOOKUP(N43,Inventory!$B:$R,12,FALSE),0)) -> 0 | P43: =IF(N43="","",IFERROR(VLOOKUP(N43,Inventory!$B:$R,15,FALSE),0)) -> 0 | Q43: =IF(N43="","",IFERROR(IF(O43=0,"Out of Stock",IF(O43<=P43,"Low Stock","In Stock")),"Out of Stock")) -> Out of Stock
...

Sheet Product Master
A1: Product ID | B1: Product Name | C1: Category | D1: Unit of Measure | E1: Cost Price | F1: Selling Price | G1: Profit per Unit | H1: Reorder Level | I1: Status
A2: P0001 | B2: Beef | C2: Food | D2: Piece | E2: 700 | F2: 1000 | G2: =Table1[[#This Row],[Selling Price]]-Table1[[#This Row],[Cost Price]] -> 300 | H2: 20 | I2: Active
A3: P0002 | B3: Shaki | C3: Food | D3: Piece | E3: 900 | F3: 1200 | G3: =Table1[[#This Row],[Selling Price]]-Table1[[#This Row],[Cost Price]] -> 300 | H3: 20 | I3: Active
A4: P0003 | B4: Cow leg | C4: Food | D4: Piece | E4: 1200 | F4: 1500 | G4: =Table1[[#This Row],[Selling Price]]-Table1[[#This Row],[Cost Price]] -> 300 | H4: 20 | I4: Active
A5: P0004 | B5: Semovita | C5: Food | D5: Piece | E5: 400 | F5: 700 | G5: =Table1[[#This Row],[Selling Price]]-Table1[[#This Row],[Cost Price]] -> 300 | H5: 20 | I5: Active
A6: P0005 | B6: Eba | C6: Food | D6: Piece | E6: 200 | F6: 500 | G6: =Table1[[#This Row],[Selling Price]]-Table1[[#This Row],[Cost Price]] -> 300 | H6: 20 | I6: Active
A7: P0006 | B7: Moin Moin | C7: Food | D7: Piece | E7: 500 | F7: 800 | G7: =Table1[[#This Row],[Selling Price]]-Table1[[#This Row],[Cost Price]] -> 300 | H7: 20 | I7: Active
A8: P0007 | B8: Meat Pie | C8: Snacks | D8: Piece | E8: 500 | F8: 900 | G8: =Table1[[#This Row],[Selling Price]]-Table1[[#This Row],[Cost Price]] -> 400 | H8: 20 | I8: Active
A9: P0008 | B9: Chicken Pie | C9: Snacks | D9: Piece | E9: 700 | F9: 1000 | G9: =Table1[[#This Row],[Selling Price]]-Table1[[#This Row],[Cost Price]] -> 300 | H9: 20 | I9: Active
A10: P0009 | B10: Beef Roll | C10: Snacks | D10: Piece | E10: 400 | F10: 700 | G10: =Table1[[#This Row],[Selling Price]]-Table1[[#This Row],[Cost Price]] -> 300 | H10: 20 | I10: Active
A11: P0010 | B11: Pet Lucozade Boost | C11: Drinks | D11: Pack | E11: 17000 | F11: 20000 | G11: =Table1[[#This Row],[Selling Price]]-Table1[[#This Row],[Cost Price]] -> 3000 | H11: 10 | I11: Active
A12: P0011 | B12: Eva Water 0.75Cl | C12: Drinks | D12: Pack | E12: 5000 | F12: 8500 | G12: =Table1[[#This Row],[Selling Price]]-Table1[[#This Row],[Cost Price]] -> 3500 | H12: 10 | I12: Active
A13: P0012 | B13: Lucozade Sport Pet 50cl | C13: Drinks | D13: Pack | E13: 900 | F13: 1500 | G13: =Table1[[#This Row],[Selling Price]]-Table1[[#This Row],[Cost Price]] -> 600 | H13: 20 | I13: Active
... A16: P0015 | B16: Malta Guinness 33cl Cans | C16: Drinks | D16: Pack | E16: 900 | F16: 1500 | G16: =Table1[[#This Row],[Selling Price]]-Table1[[#This Row],[Cost Price]] -> 600 | H16: 20 | I16: Active
G17: =Table1[[#This Row],[Selling Price]]-Table1[[#This Row],[Cost Price]] -> 0 | I17: Inactive
G18: =Table1[[#This Row],[Selling Price]]-Table1[[#This Row],[Cost Price]] -> 0 | I18: Inactive
G19: =Table1[[#This Row],[Selling Price]]-Table1[[#This Row],[Cost Price]] -> 0 | I19: Inactive
G20: =Table1[[#This Row],[Selling Price]]-Table1[[#This Row],[Cost Price]] -> 0 | I20: Inactive
G21: =Table1[[#This Row],[Selling Price]]-Table1[[#This Row],[Cost Price]] -> 0 | I21: Inactive
G22: =Table1[[#This Row],[Selling Price]]-Table1[[#This Row],[Cost Price]] -> 0 | I22: Inactive
G23: =Table1[[#This Row],[Selling Price]]-Table1[[#This Row],[Cost Price]] -> 0 | I23: Inactive
G24: =Table1[[#This Row],[Selling Price]]-Table1[[#This Row],[Cost Price]] -> 0 | I24: Inactive
G25: =Table1[[#This Row],[Selling Price]]-Table1[[#This Row],[Cost Price]] -> 0 | I25: Inactive
G26: =Table1[[#This Row],[Selling Price]]-Table1[[#This Row],[Cost Price]] -> 0 | I26: Inactive
G27: =Table1[[#This Row],[Selling Price]]-Table1[[#This Row],[Cost Price]] -> 0 | I27: Inactive
G28: =Table1[[#This Row],[Selling Price]]-Table1[[#This Row],[Cost Price]] -> 0 | I28: Inactive
... G1028: =Table1[[#This Row],[Selling Price]]-Table1[[#This Row],[Cost Price]] -> 0 | I1028: Inactive

Sheet Daily Sales Entry
A1: DATE | B1: Sales ID | C1: Cashier | D1: Product Name | E1: Category | F1: Unit | G1: QTY SOLD | H1: Selling Price | I1: Cost Price | J1: Total Sales | K1: Discount | L1: Net Sales | M1: Profit
A2: 46252 | B2: 1 | C2: Cashier 1 | D2: Beef | E2: =IF(D2="","",VLOOKUP(D2,'Product Master'!$B:$C,2,FALSE)) -> Food | F2: =IF(D2="","",IFERROR(VLOOKUP(D2,'Product Master'!$B:$G,3,FALSE),"")) -> Piece | G2: 5 | H2: =IF(D2="","",VLOOKUP(D2,'Product Master'!$B:$F,5,FALSE)) -> 1000 | I2: =IFERROR(VLOOKUP(D2,'Product Master'!B:E,4,FALSE),0) -> 700 | J2: =IFERROR(Table3[[#This Row],[QTY SOLD]]*Table3[[#This Row],[Selling Price]],0) -> 5000 | L2: =Table3[[#This Row],[Total Sales]]-Table3[[#This Row],[Discount]] -> 5000 | M2: =Table3[[#This Row],[Net Sales]]-Table3[[#This Row],[Cost Price]]*Table3[[#This Row],[QTY SOLD]] -> 1500
A3: 46252 | B3: 1 | C3: Cashier 1 | D3: Shaki | E3: =IF(D3="","",VLOOKUP(D3,'Product Master'!$B:$C,2,FALSE)) -> Food | F3: =IF(D3="","",IFERROR(VLOOKUP(D3,'Product Master'!$B:$G,3,FALSE),"")) -> Piece | G3: 4 | H3: =IF(D3="","",VLOOKUP(D3,'Product Master'!$B:$F,5,FALSE)) -> 1200 | I3: =IFERROR(VLOOKUP(D3,'Product Master'!B:E,4,FALSE),0) -> 900 | J3: =IFERROR(Table3[[#This Row],[QTY SOLD]]*Table3[[#This Row],[Selling Price]],0) -> 4800 | L3: =Table3[[#This Row],[Total Sales]]-Table3[[#This Row],[Discount]] -> 4800 | M3: =Table3[[#This Row],[Net Sales]]-Table3[[#This Row],[Cost Price]]*Table3[[#This Row],[QTY SOLD]] -> 1200
A4: 46252 | B4: 1 | C4: Cashier 1 | D4: Cow leg | E4: =IF(D4="","",VLOOKUP(D4,'Product Master'!$B:$C,2,FALSE)) -> Food | F4: =IF(D4="","",IFERROR(VLOOKUP(D4,'Product Master'!$B:$G,3,FALSE),"")) -> Piece | G4: 4 | H4: =IF(D4="","",VLOOKUP(D4,'Product Master'!$B:$F,5,FALSE)) -> 1500 | I4: =IFERROR(VLOOKUP(D4,'Product Master'!B:E,4,FALSE),0) -> 1200 | J4: =IFERROR(Table3[[#This Row],[QTY SOLD]]*Table3[[#This Row],[Selling Price]],0) -> 6000 | L4: =Table3[[#This Row],[Total Sales]]-Table3[[#This Row],[Discount]] -> 6000 | M4: =Table3[[#This Row],[Net Sales]]-Table3[[#This Row],[Cost Price]]*Table3[[#This Row],[QTY SOLD]] -> 1200
A5: 46252 | B5: 1 | C5: Cashier 1 | D5: Semovita | E5: =IF(D5="","",VLOOKUP(D5,'Product Master'!$B:$C,2,FALSE)) -> Food | F5: =IF(D5="","",IFERROR(VLOOKUP(D5,'Product Master'!$B:$G,3,FALSE),"")) -> Piece | G5: 7 | H5: =IF(D5="","",VLOOKUP(D5,'Product Master'!$B:$F,5,FALSE)) -> 700 | I5: =IFERROR(VLOOKUP(D5,'Product Master'!B:E,4,FALSE),0) -> 400 | J5: =IFERROR(Table3[[#This Row],[QTY SOLD]]*Table3[[#This Row],[Selling Price]],0) -> 4900 | L5: =Table3[[#This Row],[Total Sales]]-Table3[[#This Row],[Discount]] -> 4900 | M5: =Table3[[#This Row],[Net Sales]]-Table3[[#This Row],[Cost Price]]*Table3[[#This Row],[QTY SOLD]] -> 2100
A6: 46252 | B6: 1 | C6: Cashier 1 | D6: Eba | E6: =IF(D6="","",VLOOKUP(D6,'Product Master'!$B:$C,2,FALSE)) -> Food | F6: =IF(D6="","",IFERROR(VLOOKUP(D6,'Product Master'!$B:$G,3,FALSE),"")) -> Piece | G6: 3 | H6: =IF(D6="","",VLOOKUP(D6,'Product Master'!$B:$F,5,FALSE)) -> 500 | I6: =IFERROR(VLOOKUP(D6,'Product Master'!B:E,4,FALSE),0) -> 200 | J6: =IFERROR(Table3[[#This Row],[QTY SOLD]]*Table3[[#This Row],[Selling Price]],0) -> 1500 | L6: =Table3[[#This Row],[Total Sales]]-Table3[[#This Row],[Discount]] -> 1500 | M6: =Table3[[#This Row],[Net Sales]]-Table3[[#This Row],[Cost Price]]*Table3[[#This Row],[QTY SOLD]] -> 900
A7: 46252 | B7: 1 | C7: Cashier 1 | D7: Moin Moin | E7: =IF(D7="","",VLOOKUP(D7,'Product Master'!$B:$C,2,FALSE)) -> Food | F7: =IF(D7="","",IFERROR(VLOOKUP(D7,'Product Master'!$B:$G,3,FALSE),"")) -> Piece | G7: 6 | H7: =IF(D7="","",VLOOKUP(D7,'Product Master'!$B:$F,5,FALSE)) -> 800 | I7: =IFERROR(VLOOKUP(D7,'Product Master'!B:E,4,FALSE),0) -> 500 | J7: =IFERROR(Table3[[#This Row],[QTY SOLD]]*Table3[[#This Row],[Selling Price]],0) -> 4800 | L7: =Table3[[#This Row],[Total Sales]]-Table3[[#This Row],[Discount]] -> 4800 | M7: =Table3[[#This Row],[Net Sales]]-Table3[[#This Row],[Cost Price]]*Table3[[#This Row],[QTY SOLD]] -> 1800
A8: =A7+1 -> 46253 | B8: 2 | C8: Cashier 3 | D8: Cow leg | E8: =IF(D8="","",VLOOKUP(D8,'Product Master'!$B:$C,2,FALSE)) -> Food | F8: =IF(D8="","",IFERROR(VLOOKUP(D8,'Product Master'!$B:$G,3,FALSE),"")) -> Piece | G8: 4 | H8: =IF(D8="","",VLOOKUP(D8,'Product Master'!$B:$F,5,FALSE)) -> 1500 | I8: =IFERROR(VLOOKUP(D8,'Product Master'!B:E,4,FALSE),0) -> 1200 | J8: =IFERROR(Table3[[#This Row],[QTY SOLD]]*Table3[[#This Row],[Selling Price]],0) -> 6000 | L8: =Table3[[#This Row],[Total Sales]]-Table3[[#This Row],[Discount]] -> 6000 | M8: =Table3[[#This Row],[Net Sales]]-Table3[[#This Row],[Cost Price]]*Table3[[#This Row],[QTY SOLD]] -> 1200
A9: 46251 | B9: 3 | C9: Cashier 5 | D9: Beef | E9: =IF(D9="","",VLOOKUP(D9,'Product Master'!$B:$C,2,FALSE)) -> Food | F9: =IF(D9="","",IFERROR(VLOOKUP(D9,'Product Master'!$B:$G,3,FALSE),"")) -> Piece | G9: 6 | H9: =IF(D9="","",VLOOKUP(D9,'Product Master'!$B:$F,5,FALSE)) -> 1000 | I9: =IFERROR(VLOOKUP(D9,'Product Master'!B:E,4,FALSE),0) -> 700 | J9: =IFERROR(Table3[[#This Row],[QTY SOLD]]*Table3[[#This Row],[Selling Price]],0) -> 6000 | L9: =Table3[[#This Row],[Total Sales]]-Table3[[#This Row],[Discount]] -> 6000 | M9: =Table3[[#This Row],[Net Sales]]-Table3[[#This Row],[Cost Price]]*Table3[[#This Row],[QTY SOLD]] -> 1800
A10: 46255 | B10: 4 | C10: Cashier 3 | D10: Shaki | E10: =IF(D10="","",VLOOKUP(D10,'Product Master'!$B:$C,2,FALSE)) -> Food | F10: =IF(D10="","",IFERROR(VLOOKUP(D10,'Product Master'!$B:$G,3,FALSE),"")) -> Piece | G10: 15 | H10: =IF(D10="","",VLOOKUP(D10,'Product Master'!$B:$F,5,FALSE)) -> 1200 | I10: =IFERROR(VLOOKUP(D10,'Product Master'!B:E,4,FALSE),0) -> 900 | J10: =IFERROR(Table3[[#This Row],[QTY SOLD]]*Table3[[#This Row],[Selling Price]],0) -> 18000 | L10: =Table3[[#This Row],[Total Sales]]-Table3[[#This Row],[Discount]] -> 18000 | M10: =Table3[[#This Row],[Net Sales]]-Table3[[#This Row],[Cost Price]]*Table3[[#This Row],[QTY SOLD]] -> 4500
A11: 46255 | B11: 4 | C11: Cashier 5 | D11: Moin Moin | E11: =IF(D11="","",VLOOKUP(D11,'Product Master'!$B:$C,2,FALSE)) -> Food | F11: =IF(D11="","",IFERROR(VLOOKUP(D11,'Product Master'!$B:$G,3,FALSE),"")) -> Piece | G11: 13 | H11: =IF(D11="","",VLOOKUP(D11,'Product Master'!$B:$F,5,FALSE)) -> 800 | I11: =IFERROR(VLOOKUP(D11,'Product Master'!B:E,4,FALSE),0) -> 500 | J11: =IFERROR(Table3[[#This Row],[QTY SOLD]]*Table3[[#This Row],[Selling Price]],0) -> 10400 | L11: =Table3[[#This Row],[Total Sales]]-Table3[[#This Row],[Discount]] -> 10400 | M11: =Table3[[#This Row],[Net Sales]]-Table3[[#This Row],[Cost Price]]*Table3[[#This Row],[QTY SOLD]] -> 3900
A12: 46255 | B12: 5 | C12: Cashier 3 | D12: Meat Pie | E12: =IF(D12="","",VLOOKUP(D12,'Product Master'!$B:$C,2,FALSE)) -> Snacks | F12: =IF(D12="","",IFERROR(VLOOKUP(D12,'Product Master'!$B:$G,3,FALSE),"")) -> Piece | G12: 3 | H12: =IF(D12="","",VLOOKUP(D12,'Product Master'!$B:$F,5,FALSE)) -> 900 | I12: =IFERROR(VLOOKUP(D12,'Product Master'!B:E,4,FALSE),0) -> 500 | J12: =IFERROR(Table3[[#This Row],[QTY SOLD]]*Table3[[#This Row],[Selling Price]],0) -> 2700 | L12: =Table3[[#This Row],[Total Sales]]-Table3[[#This Row],[Discount]] -> 2700 | M12: =Table3[[#This Row],[Net Sales]]-Table3[[#This Row],[Cost Price]]*Table3[[#This Row],[QTY SOLD]] -> 1200
A13: 46255 | B13: 5 | C13: Cashier 3 | D13: Chicken Pie | E13: =IF(D13="","",VLOOKUP(D13,'Product Master'!$B:$C,2,FALSE)) -> Snacks | F13: =IF(D13="","",IFERROR(VLOOKUP(D13,'Product Master'!$B:$G,3,FALSE),"")) -> Piece | G13: 7 | H13: =IF(D13="","",VLOOKUP(D13,'Product Master'!$B:$F,5,FALSE)) -> 1000 | I13: =IFERROR(VLOOKUP(D13,'Product Master'!B:E,4,FALSE),0) -> 700 | J13: =IFERROR(Table3[[#This Row],[QTY SOLD]]*Table3[[#This Row],[Selling Price]],0) -> 7000 | L13: =Table3[[#This Row],[Total Sales]]-Table3[[#This Row],[Discount]] -> 7000 | M13: =Table3[[#This Row],[Net Sales]]-Table3[[#This Row],[Cost Price]]*Table3[[#This Row],[QTY SOLD]] -> 2100
A14: 46255 | B14: 5 | C14: Cashier 3 | D14: Beef Roll | E14: =IF(D14="","",VLOOKUP(D14,'Product Master'!$B:$C,2,FALSE)) -> Snacks | F14: =IF(D14="","",IFERROR(VLOOKUP(D14,'Product Master'!$B:$G,3,FALSE),"")) -> Piece | G14: 5 | H14: =IF(D14="","",VLOOKUP(D14,'Product Master'!$B:$F,5,FALSE)) -> 700 | I14: =IFERROR(VLOOKUP(D14,'Product Master'!B:E,4,FALSE),0) -> 400 | J14: =IFERROR(Table3[[#This Row],[QTY SOLD]]*Table3[[#This Row],[Selling Price]],0) -> 3500 | L14: =Table3[[#This Row],[Total Sales]]-Table3[[#This Row],[Discount]] -> 3500 | M14: =Table3[[#This Row],[Net Sales]]-Table3[[#This Row],[Cost Price]]*Table3[[#This Row],[QTY SOLD]] -> 1500
A15: 46258 | B15: 6 | C15: Cashier 1 | D15: Pet Lucozade Boost | E15: =IF(D15="","",VLOOKUP(D15,'Product Master'!$B:$C,2,FALSE)) -> Drinks | F15: =IF(D15="","",IFERROR(VLOOKUP(D15,'Product Master'!$B:$G,3,FALSE),"")) -> Pack | G15: 5 | H15: =IF(D15="","",VLOOKUP(D15,'Product Master'!$B:$F,5,FALSE)) -> 20000 | I15: =IFERROR(VLOOKUP(D15,'Product Master'!B:E,4,FALSE),0) -> 17000 | J15: =IFERROR(Table3[[#This Row],[QTY SOLD]]*Table3[[#This Row],[Selling Price]],0) -> 100000 | L15: =Table3[[#This Row],[Total Sales]]-Table3[[#This Row],[Discount]] -> 100000 | M15: =Table3[[#This Row],[Net Sales]]-Table3[[#This Row],[Cost Price]]*Table3[[#This Row],[QTY SOLD]] -> 15000
A16: 46258 | B16: 6 | C16: Cashier 1 | D16: Eva Water 0.75Cl | E16: =IF(D16="","",VLOOKUP(D16,'Product Master'!$B:$C,2,FALSE)) -> Drinks | F16: =IF(D16="","",IFERROR(VLOOKUP(D16,'Product Master'!$B:$G,3,FALSE),"")) -> Pack | G16: 7 | H16: =IF(D16="","",VLOOKUP(D16,'Product Master'!$B:$F,5,FALSE)) -> 8500 | I16: =IFERROR(VLOOKUP(D16,'Product Master'!B:E,4,FALSE),0) -> 5000 | J16: =IFERROR(Table3[[#This Row],[QTY SOLD]]*Table3[[#This Row],[Selling Price]],0) -> 59500 | L16: =Table3[[#This Row],[Total Sales]]-Table3[[#This Row],[Discount]] -> 59500 | M16: =Table3[[#This Row],[Net Sales]]-Table3[[#This Row],[Cost Price]]*Table3[[#This Row],[QTY SOLD]] -> 24500
A17: =A16+1 -> 46259 | B17: 6 | C17: Cashier 2 | D17: Beef | E17: =IF(D17="","",VLOOKUP(D17,'Product Master'!$B:$C,2,FALSE)) -> Food | F17: =IF(D17="","",IFERROR(VLOOKUP(D17,'Product Master'!$B:$G,3,FALSE),"")) -> Piece | G17: 5 | H17: =IF(D17="","",VLOOKUP(D17,'Product Master'!$B:$F,5,FALSE)) -> 1000 | I17: =IFERROR(VLOOKUP(D17,'Product Master'!B:E,4,FALSE),0) -> 700 | J17: =IFERROR(Table3[[#This Row],[QTY SOLD]]*Table3[[#This Row],[Selling Price]],0) -> 5000 | L17: =Table3[[#This Row],[Total Sales]]-Table3[[#This Row],[Discount]] -> 5000 | M17: =Table3[[#This Row],[Net Sales]]-Table3[[#This Row],[Cost Price]]*Table3[[#This Row],[QTY SOLD]] -> 1500
A18: =A17+1 -> 46260 | B18: 6 | C18: Cashier 1 | D18: Shaki | E18: =IF(D18="","",VLOOKUP(D18,'Product Master'!$B:$C,2,FALSE)) -> Food | F18: =IF(D18="","",IFERROR(VLOOKUP(D18,'Product Master'!$B:$G,3,FALSE),"")) -> Piece | G18: 8 | H18: =IF(D18="","",VLOOKUP(D18,'Product Master'!$B:$F,5,FALSE)) -> 1200 | I18: =IFERROR(VLOOKUP(D18,'Product Master'!B:E,4,FALSE),0) -> 900 | J18: =IFERROR(Table3[[#This Row],[QTY SOLD]]*Table3[[#This Row],[Selling Price]],0) -> 9600 | L18: =Table3[[#This Row],[Total Sales]]-Table3[[#This Row],[Discount]] -> 9600 | M18: =Table3[[#This Row],[Net Sales]]-Table3[[#This Row],[Cost Price]]*Table3[[#This Row],[QTY SOLD]] -> 2400
A19: 46265 | B19: 7 | C19: Cashier 2 | D19: Lucozade Sport Pet 50cl | E19: =IF(D19="","",VLOOKUP(D19,'Product Master'!$B:$C,2,FALSE)) -> Drinks | F19: =IF(D19="","",IFERROR(VLOOKUP(D19,'Product Master'!$B:$G,3,FALSE),"")) -> Pack | G19: 5 | H19: =IF(D19="","",VLOOKUP(D19,'Product Master'!$B:$F,5,FALSE)) -> 1500 | I19: =IFERROR(VLOOKUP(D19,'Product Master'!B:E,4,FALSE),0) -> 900 | J19: =IFERROR(Table3[[#This Row],[QTY SOLD]]*Table3[[#This Row],[Selling Price]],0) -> 7500 | L19: =Table3[[#This Row],[Total Sales]]-Table3[[#This Row],[Discount]] -> 7500 | M19: =Table3[[#This Row],[Net Sales]]-Table3[[#This Row],[Cost Price]]*Table3[[#This Row],[QTY SOLD]] -> 3000
A20: 46265 | B20: 7 | C20: Cashier 2 | D20: FAB Energy Drinks | E20: =IF(D20="","",VLOOKUP(D20,'Product Master'!$B:$C,2,FALSE)) -> Drinks | F20: =IF(D20="","",IFERROR(VLOOKUP(D20,'Product Master'!$B:$G,3,FALSE),"")) -> Pack | G20: 5 | H20: =IF(D20="","",VLOOKUP(D20,'Product Master'!$B:$F,5,FALSE)) -> 1500 | I20: =IFERROR(VLOOKUP(D20,'Product Master'!B:E,4,FALSE),0) -> 1000 | J20: =IFERROR(Table3[[#This Row],[QTY SOLD]]*Table3[[#This Row],[Selling Price]],0) -> 7500 | L20: =Table3[[#This Row],[Total Sales]]-Table3[[#This Row],[Discount]] -> 7500 | M20: =Table3[[#This Row],[Net Sales]]-Table3[[#This Row],[Cost Price]]*Table3[[#This Row],[QTY SOLD]] -> 2500
A21: 46265 | B21: 7 | C21: Cashier 2 | D21: Chin Chin 224 gms | E21: =IF(D21="","",VLOOKUP(D21,'Product Master'!$B:$C,2,FALSE)) -> Snacks | F21: =IF(D21="","",IFERROR(VLOOKUP(D21,'Product Master'!$B:$G,3,FALSE),"")) -> Piece | G21: 5 | H21: =IF(D21="","",VLOOKUP(D21,'Product Master'!$B:$F,5,FALSE)) -> 1500 | I21: =IFERROR(VLOOKUP(D21,'Product Master'!B:E,4,FALSE),0) -> 800 | J21: =IFERROR(Table3[[#This Row],[QTY SOLD]]*Table3[[#This Row],[Selling Price]],0) -> 7500 | L21: =Table3[[#This Row],[Total Sales]]-Table3[[#This Row],[Discount]] -> 7500 | M21: =Table3[[#This Row],[Net Sales]]-Table3[[#This Row],[Cost Price]]*Table3[[#This Row],[QTY SOLD]] -> 3500
A22: 46265 | B22: 7 | C22: Cashier 2 | D22: Malta Guinness 33cl Cans | E22: =IF(D22="","",VLOOKUP(D22,'Product Master'!$B:$C,2,FALSE)) -> Drinks | F22: =IF(D22="","",IFERROR(VLOOKUP(D22,'Product Master'!$B:$G,3,FALSE),"")) -> Pack | G22: 5 | H22: =IF(D22="","",VLOOKUP(D22,'Product Master'!$B:$F,5,FALSE)) -> 1500 | I22: =IFERROR(VLOOKUP(D22,'Product Master'!B:E,4,FALSE),0) -> 900 | J22: =IFERROR(Table3[[#This Row],[QTY SOLD]]*Table3[[#This Row],[Selling Price]],0) -> 7500 | L22: =Table3[[#This Row],[Total Sales]]-Table3[[#This Row],[Discount]] -> 7500 | M22: =Table3[[#This Row],[Net Sales]]-Table3[[#This Row],[Cost Price]]*Table3[[#This Row],[QTY SOLD]] -> 3000
A23: =A22+1 -> 46266 | E23: =IF(D23="","",VLOOKUP(D23,'Product Master'!$B:$C,2,FALSE)) | F23: =IF(D23="","",IFERROR(VLOOKUP(D23,'Product Master'!$B:$G,3,FALSE),"")) | H23: =IF(D23="","",VLOOKUP(D23,'Product Master'!$B:$F,5,FALSE)) | I23: =IFERROR(VLOOKUP(D23,'Product Master'!B:E,4,FALSE),0) -> 0 | J23: =IFERROR(Table3[[#This Row],[QTY SOLD]]*Table3[[#This Row],[Selling Price]],0) -> 0 | L23: =Table3[[#This Row],[Total Sales]]-Table3[[#This Row],[Discount]] -> 0 | M23: =Table3[[#This Row],[Net Sales]]-Table3[[#This Row],[Cost Price]]*Table3[[#This Row],[QTY SOLD]] -> 0
A24: =A23+1 -> 46267 | E24: =IF(D24="","",VLOOKUP(D24,'Product Master'!$B:$C,2,FALSE)) | F24: =IF(D24="","",IFERROR(VLOOKUP(D24,'Product Master'!$B:$G,3,FALSE),"")) | H24: =IF(D24="","",VLOOKUP(D24,'Product Master'!$B:$F,5,FALSE)) | I24: =IFERROR(VLOOKUP(D24,'Product Master'!B:E,4,FALSE),0) -> 0 | J24: =IFERROR(Table3[[#This Row],[QTY SOLD]]*Table3[[#This Row],[Selling Price]],0) -> 0 | L24: =Table3[[#This Row],[Total Sales]]-Table3[[#This Row],[Discount]] -> 0 | M24: =Table3[[#This Row],[Net Sales]]-Table3[[#This Row],[Cost Price]]*Table3[[#This Row],[QTY SOLD]] -> 0
A25: =A24+1 -> 46268 | E25: =IF(D25="","",VLOOKUP(D25,'Product Master'!$B:$C,2,FALSE)) | F25: =IF(D25="","",IFERROR(VLOOKUP(D25,'Product Master'!$B:$G,3,FALSE),"")) | H25: =IF(D25="","",VLOOKUP(D25,'Product Master'!$B:$F,5,FALSE)) | I25: =IFERROR(VLOOKUP(D25,'Product Master'!B:E,4,FALSE),0) -> 0 | J25: =IFERROR(Table3[[#This Row],[QTY SOLD]]*Table3[[#This Row],[Selling Price]],0) -> 0 | L25: =Table3[[#This Row],[Total Sales]]-Table3[[#This Row],[Discount]] -> 0 | M25: =Table3[[#This Row],[Net Sales]]-Table3[[#This Row],[Cost Price]]*Table3[[#This Row],[QTY SOLD]] -> 0
A26: =A25+1 -> 46269 | E26: =IF(D26="","",VLOOKUP(D26,'Product Master'!$B:$C,2,FALSE)) | F26: =IF(D26="","",IFERROR(VLOOKUP(D26,'Product Master'!$B:$G,3,FALSE),"")) | H26: =IF(D26="","",VLOOKUP(D26,'Product Master'!$B:$F,5,FALSE)) | I26: =IFERROR(VLOOKUP(D26,'Product Master'!B:E,4,FALSE),0) -> 0 | J26: =IFERROR(Table3[[#This Row],[QTY SOLD]]*Table3[[#This Row],[Selling Price]],0) -> 0 | L26: =Table3[[#This Row],[Total Sales]]-Table3[[#This Row],[Discount]] -> 0 | M26: =Table3[[#This Row],[Net Sales]]-Table3[[#This Row],[Cost Price]]*Table3[[#This Row],[QTY SOLD]] -> 0
A27: =A26+1 -> 46270 | E27: =IF(D27="","",VLOOKUP(D27,'Product Master'!$B:$C,2,FALSE)) | F27: =IF(D27="","",IFERROR(VLOOKUP(D27,'Product Master'!$B:$G,3,FALSE),"")) | H27: =IF(D27="","",VLOOKUP(D27,'Product Master'!$B:$F,5,FALSE)) | I27: =IFERROR(VLOOKUP(D27,'Product Master'!B:E,4,FALSE),0) -> 0 | J27: =IFERROR(Table3[[#This Row],[QTY SOLD]]*Table3[[#This Row],[Selling Price]],0) -> 0 | L27: =Table3[[#This Row],[Total Sales]]-Table3[[#This Row],[Discount]] -> 0 | M27: =Table3[[#This Row],[Net Sales]]-Table3[[#This Row],[Cost Price]]*Table3[[#This Row],[QTY SOLD]] -> 0
A28: =A27+1 -> 46271 | E28: =IF(D28="","",VLOOKUP(D28,'Product Master'!$B:$C,2,FALSE)) | F28: =IF(D28="","",IFERROR(VLOOKUP(D28,'Product Master'!$B:$G,3,FALSE),"")) | H28: =IF(D28="","",VLOOKUP(D28,'Product Master'!$B:$F,5,FALSE)) | I28: =IFERROR(VLOOKUP(D28,'Product Master'!B:E,4,FALSE),0) -> 0 | J28: =IFERROR(Table3[[#This Row],[QTY SOLD]]*Table3[[#This Row],[Selling Price]],0) -> 0 | L28: =Table3[[#This Row],[Total Sales]]-Table3[[#This Row],[Discount]] -> 0 | M28: =Table3[[#This Row],[Net Sales]]-Table3[[#This Row],[Cost Price]]*Table3[[#This Row],[QTY SOLD]] -> 0
A29: =A28+1 -> 46272 | E29: =IF(D29="","",VLOOKUP(D29,'Product Master'!$B:$C,2,FALSE)) | F29: =IF(D29="","",IFERROR(VLOOKUP(D29,'Product Master'!$B:$G,3,FALSE),"")) | H29: =IF(D29="","",VLOOKUP(D29,'Product Master'!$B:$F,5,FALSE)) | I29: =IFERROR(VLOOKUP(D29,'Product Master'!B:E,4,FALSE),0) -> 0 | J29: =IFERROR(Table3[[#This Row],[QTY SOLD]]*Table3[[#This Row],[Selling Price]],0) -> 0 | L29: =Table3[[#This Row],[Total Sales]]-Table3[[#This Row],[Discount]] -> 0 | M29: =Table3[[#This Row],[Net Sales]]-Table3[[#This Row],[Cost Price]]*Table3[[#This Row],[QTY SOLD]] -> 0
A30: =A29+1 -> 46273 | E30: =IF(D30="","",VLOOKUP(D30,'Product Master'!$B:$C,2,FALSE)) | F30: =IF(D30="","",IFERROR(VLOOKUP(D30,'Product Master'!$B:$G,3,FALSE),"")) | H30: =IF(D30="","",VLOOKUP(D30,'Product Master'!$B:$F,5,FALSE)) | I30: =IFERROR(VLOOKUP(D30,'Product Master'!B:E,4,FALSE),0) -> 0 | J30: =IFERROR(Table3[[#This Row],[QTY SOLD]]*Table3[[#This Row],[Selling Price]],0) -> 0 | L30: =Table3[[#This Row],[Total Sales]]-Table3[[#This Row],[Discount]] -> 0 | M30: =Table3[[#This Row],[Net Sales]]-Table3[[#This Row],[Cost Price]]*Table3[[#This Row],[QTY SOLD]] -> 0
A31: =A30+1 -> 46274 | E31: =IF(D31="","",VLOOKUP(D31,'Product Master'!$B:$C,2,FALSE)) | F31: =IF(D31="","",IFERROR(VLOOKUP(D31,'Product Master'!$B:$G,3,FALSE),"")) | H31: =IF(D31="","",VLOOKUP(D31,'Product Master'!$B:$F,5,FALSE)) | I31: =IFERROR(VLOOKUP(D31,'Product Master'!B:E,4,FALSE),0) -> 0 | J31: =IFERROR(Table3[[#This Row],[QTY SOLD]]*Table3[[#This Row],[Selling Price]],0) -> 0 | L31: =Table3[[#This Row],[Total Sales]]-Table3[[#This Row],[Discount]] -> 0 | M31: =Table3[[#This Row],[Net Sales]]-Table3[[#This Row],[Cost Price]]*Table3[[#This Row],[QTY SOLD]] -> 0
A32: =A31+1 -> 46275 | E32: =IF(D32="","",VLOOKUP(D32,'Product Master'!$B:$C,2,FALSE)) | F32: =IF(D32="","",IFERROR(VLOOKUP(D32,'Product Master'!$B:$G,3,FALSE),"")) | H32: =IF(D32="","",VLOOKUP(D32,'Product Master'!$B:$F,5,FALSE)) | I32: =IFERROR(VLOOKUP(D32,'Product Master'!B:E,4,FALSE),0) -> 0 | J32: =IFERROR(Table3[[#This Row],[QTY SOLD]]*Table3[[#This Row],[Selling Price]],0) -> 0 | L32: =Table3[[#This Row],[Total Sales]]-Table3[[#This Row],[Discount]] -> 0 | M32: =Table3[[#This Row],[Net Sales]]-Table3[[#This Row],[Cost Price]]*Table3[[#This Row],[QTY SOLD]] -> 0
E33: =IF(D33="","",VLOOKUP(D33,'Product Master'!$B:$C,2,FALSE)) | F33: =IF(D33="","",IFERROR(VLOOKUP(D33,'Product Master'!$B:$G,3,FALSE),"")) | H33: =IF(D33="","",VLOOKUP(D33,'Product Master'!$B:$F,5,FALSE)) | I33: =IFERROR(VLOOKUP(D33,'Product Master'!B:E,4,FALSE),0) -> 0 | J33: =IFERROR(Table3[[#This Row],[QTY SOLD]]*Table3[[#This Row],[Selling Price]],0) -> 0 | L33: =Table3[[#This Row],[Total Sales]]-Table3[[#This Row],[Discount]] -> 0 | M33: =Table3[[#This Row],[Net Sales]]-Table3[[#This Row],[Cost Price]]*Table3[[#This Row],[QTY SOLD]] -> 0
E34: =IF(D34="","",VLOOKUP(D34,'Product Master'!$B:$C,2,FALSE)) | F34: =IF(D34="","",IFERROR(VLOOKUP(D34,'Product Master'!$B:$G,3,FALSE),"")) | H34: =IF(D34="","",VLOOKUP(D34,'Product Master'!$B:$F,5,FALSE)) | I34: =IFERROR(VLOOKUP(D34,'Product Master'!B:E,4,FALSE),0) -> 0 | J34: =IFERROR(Table3[[#This Row],[QTY SOLD]]*Table3[[#This Row],[Selling Price]],0) -> 0 | L34: =Table3[[#This Row],[Total Sales]]-Table3[[#This Row],[Discount]] -> 0 | M34: =Table3[[#This Row],[Net Sales]]-Table3[[#This Row],[Cost Price]]*Table3[[#This Row],[QTY SOLD]] -> 0
E35: =IF(D35="","",VLOOKUP(D35,'Product Master'!$B:$C,2,FALSE)) | F35: =IF(D35="","",IFERROR(VLOOKUP(D35,'Product Master'!$B:$G,3,FALSE),"")) | H35: =IF(D35="","",VLOOKUP(D35,'Product Master'!$B:$F,5,FALSE)) | I35: =IFERROR(VLOOKUP(D35,'Product Master'!B:E,4,FALSE),0) -> 0 | J35: =IFERROR(Table3[[#This Row],[QTY SOLD]]*Table3[[#This Row],[Selling Price]],0) -> 0 | L35: =Table3[[#This Row],[Total Sales]]-Table3[[#This Row],[Discount]] -> 0 | M35: =Table3[[#This Row],[Net Sales]]-Table3[[#This Row],[Cost Price]]*Table3[[#This Row],[QTY SOLD]] -> 0
E36: =IF(D36="","",VLOOKUP(D36,'Product Master'!$B:$C,2,FALSE)) | F36: =IF(D36="","",IFERROR(VLOOKUP(D36,'Product Master'!$B:$G,3,FALSE),"")) | H36: =IF(D36="","",VLOOKUP(D36,'Product Master'!$B:$F,5,FALSE)) | I36: =IFERROR(VLOOKUP(D36,'Product Master'!B:E,4,FALSE),0) -> 0 | J36: =IFERROR(Table3[[#This Row],[QTY SOLD]]*Table3[[#This Row],[Selling Price]],0) -> 0 | L36: =Table3[[#This Row],[Total Sales]]-Table3[[#This Row],[Discount]] -> 0 | M36: =Table3[[#This Row],[Net Sales]]-Table3[[#This Row],[Cost Price]]*Table3[[#This Row],[QTY SOLD]] -> 0
E37: =IF(D37="","",VLOOKUP(D37,'Product Master'!$B:$C,2,FALSE)) | F37: =IF(D37="","",IFERROR(VLOOKUP(D37,'Product Master'!$B:$G,3,FALSE),"")) | H37: =IF(D37="","",VLOOKUP(D37,'Product Master'!$B:$F,5,FALSE)) | I37: =IFERROR(VLOOKUP(D37,'Product Master'!B:E,4,FALSE),0) -> 0 | J37: =IFERROR(Table3[[#This Row],[QTY SOLD]]*Table3[[#This Row],[Selling Price]],0) -> 0 | L37: =Table3[[#This Row],[Total Sales]]-Table3[[#This Row],[Discount]] -> 0 | M37: =Table3[[#This Row],[Net Sales]]-Table3[[#This Row],[Cost Price]]*Table3[[#This Row],[QTY SOLD]] -> 0
E38: =IF(D38="","",VLOOKUP(D38,'Product Master'!$B:$C,2,FALSE)) | F38: =IF(D38="","",IFERROR(VLOOKUP(D38,'Product Master'!$B:$G,3,FALSE),"")) | H38: =IF(D38="","",VLOOKUP(D38,'Product Master'!$B:$F,5,FALSE)) | I38: =IFERROR(VLOOKUP(D38,'Product Master'!B:E,4,FALSE),0) -> 0 | J38: =IFERROR(Table3[[#This Row],[QTY SOLD]]*Table3[[#This Row],[Selling Price]],0) -> 0 | L38: =Table3[[#This Row],[Total Sales]]-Table3[[#This Row],[Discount]] -> 0 | M38: =Table3[[#This Row],[Net Sales]]-Table3[[#This Row],[Cost Price]]*Table3[[#This Row],[QTY SOLD]] -> 0
E39: =IF(D39="","",VLOOKUP(D39,'Product Master'!$B:$C,2,FALSE)) | F39: =IF(D39="","",IFERROR(VLOOKUP(D39,'Product Master'!$B:$G,3,FALSE),"")) | H39: =IF(D39="","",VLOOKUP(D39,'Product Master'!$B:$F,5,FALSE)) | I39: =IFERROR(VLOOKUP(D39,'Product Master'!B:E,4,FALSE),0) -> 0 | J39: =IFERROR(Table3[[#This Row],[QTY SOLD]]*Table3[[#This Row],[Selling Price]],0) -> 0 | L39: =Table3[[#This Row],[Total Sales]]-Table3[[#This Row],[Discount]] -> 0 | M39: =Table3[[#This Row],[Net Sales]]-Table3[[#This Row],[Cost Price]]*Table3[[#This Row],[QTY SOLD]] -> 0
E40: =IF(D40="","",VLOOKUP(D40,'Product Master'!$B:$C,2,FALSE)) | F40: =IF(D40="","",IFERROR(VLOOKUP(D40,'Product Master'!$B:$G,3,FALSE),"")) | H40: =IF(D40="","",VLOOKUP(D40,'Product Master'!$B:$F,5,FALSE)) | I40: =IFERROR(VLOOKUP(D40,'Product Master'!B:E,4,FALSE),0) -> 0 | J40: =IFERROR(Table3[[#This Row],[QTY SOLD]]*Table3[[#This Row],[Selling Price]],0) -> 0 | L40: =Table3[[#This Row],[Total Sales]]-Table3[[#This Row],[Discount]] -> 0 | M40: =Table3[[#This Row],[Net Sales]]-Table3[[#This Row],[Cost Price]]*Table3[[#This Row],[QTY SOLD]] -> 0
...

Sheet Stock Purchase
A1: Date | B1: Purchase ID | C1: Supplier | D1: Product Name | E1: Unit | F1: QTY Purchased | G1: Unit Cost | H1: Total Purchase Cost
A2: 46235 | B2: ="PUR"&TEXT(ROW()-1,"0000") -> PUR0001 | C2: Supplier 1 | D2: Beef | E2: =IF(D2="","",VLOOKUP(D2,'Product Master'!$B:$G,3,FALSE)) -> Piece | F2: 50 | G2: =IF(D2="","",VLOOKUP(D2,'Product Master'!$B:$G,4,FALSE)) -> 700 | H2: =IF(OR(F2="",G2=""),"",F2*G2) -> 35000
A3: 46236 | B3: ="PUR"&TEXT(ROW()-1,"0000") -> PUR0002 | C3: Supplier 1 | D3: Shaki | E3: =IF(D3="","",VLOOKUP(D3,'Product Master'!$B:$G,3,FALSE)) -> Piece | F3: 50 | G3: =IF(D3="","",VLOOKUP(D3,'Product Master'!$B:$G,4,FALSE)) -> 900 | H3: =IF(OR(F3="",G3=""),"",F3*G3) -> 45000
A4: 46237 | B4: ="PUR"&TEXT(ROW()-1,"0000") -> PUR0003 | C4: Supplier 1 | D4: Cow leg | E4: =IF(D4="","",VLOOKUP(D4,'Product Master'!$B:$G,3,FALSE)) -> Piece | F4: 50 | G4: =IF(D4="","",VLOOKUP(D4,'Product Master'!$B:$G,4,FALSE)) -> 1200 | H4: =IF(OR(F4="",G4=""),"",F4*G4) -> 60000
A5: 46238 | B5: ="PUR"&TEXT(ROW()-1,"0000") -> PUR0004 | C5: Supplier 1 | D5: Semovita | E5: =IF(D5="","",VLOOKUP(D5,'Product Master'!$B:$G,3,FALSE)) -> Piece | F5: 50 | G5: =IF(D5="","",VLOOKUP(D5,'Product Master'!$B:$G,4,FALSE)) -> 400 | H5: =IF(OR(F5="",G5=""),"",F5*G5) -> 20000
A6: 46239 | B6: ="PUR"&TEXT(ROW()-1,"0000") -> PUR0005 | C6: Supplier 1 | D6: Eba | E6: =IF(D6="","",VLOOKUP(D6,'Product Master'!$B:$G,3,FALSE)) -> Piece | F6: 50 | G6: =IF(D6="","",VLOOKUP(D6,'Product Master'!$B:$G,4,FALSE)) -> 200 | H6: =IF(OR(F6="",G6=""),"",F6*G6) -> 10000
A7: 46240 | B7: ="PUR"&TEXT(ROW()-1,"0000") -> PUR0006 | C7: Supplier 1 | D7: Moin Moin | E7: =IF(D7="","",VLOOKUP(D7,'Product Master'!$B:$G,3,FALSE)) -> Piece | F7: 50 | G7: =IF(D7="","",VLOOKUP(D7,'Product Master'!$B:$G,4,FALSE)) -> 500 | H7: =IF(OR(F7="",G7=""),"",F7*G7) -> 25000
A8: 46255 | B8: ="PUR"&TEXT(ROW()-1,"0000") -> PUR0007 | C8: Supplier 3 | D8: Meat Pie | E8: =IF(D8="","",VLOOKUP(D8,'Product Master'!$B:$G,3,FALSE)) -> Piece | F8: 50 | G8: =IF(D8="","",VLOOKUP(D8,'Product Master'!$B:$G,4,FALSE)) -> 500 | H8: =IF(OR(F8="",G8=""),"",F8*G8) -> 25000
A9: 46242 | B9: ="PUR"&TEXT(ROW()-1,"0000") -> PUR0008 | C9: Supplier 3 | D9: Chicken Pie | E9: =IF(D9="","",VLOOKUP(D9,'Product Master'!$B:$G,3,FALSE)) -> Piece | F9: 50 | G9: =IF(D9="","",VLOOKUP(D9,'Product Master'!$B:$G,4,FALSE)) -> 700 | H9: =IF(OR(F9="",G9=""),"",F9*G9) -> 35000
A10: 46243 | B10: ="PUR"&TEXT(ROW()-1,"0000") -> PUR0009 | C10: Supplier 3 | D10: Beef Roll | E10: =IF(D10="","",VLOOKUP(D10,'Product Master'!$B:$G,3,FALSE)) -> Piece | F10: 50 | G10: =IF(D10="","",VLOOKUP(D10,'Product Master'!$B:$G,4,FALSE)) -> 400 | H10: =IF(OR(F10="",G10=""),"",F10*G10) -> 20000
A11: 46244 | B11: ="PUR"&TEXT(ROW()-1,"0000") -> PUR0010 | C11: Supplier 1 | D11: Pet Lucozade Boost | E11: =IF(D11="","",VLOOKUP(D11,'Product Master'!$B:$G,3,FALSE)) -> Pack | F11: 70 | G11: =IF(D11="","",VLOOKUP(D11,'Product Master'!$B:$G,4,FALSE)) -> 17000 | H11: =IF(OR(F11="",G11=""),"",F11*G11) -> 1190000
A12: 46245 | B12: ="PUR"&TEXT(ROW()-1,"0000") -> PUR0011 | C12: Supplier 1 | D12: Eva Water 0.75Cl | E12: =IF(D12="","",VLOOKUP(D12,'Product Master'!$B:$G,3,FALSE)) -> Pack | F12: 70 | G12: =IF(D12="","",VLOOKUP(D12,'Product Master'!$B:$G,4,FALSE)) -> 5000 | H12: =IF(OR(F12="",G12=""),"",F12*G12) -> 350000
A13: 46265 | B13: ="PUR"&TEXT(ROW()-1,"0000") -> PUR0012 | C13: Supplier 3 | D13: Lucozade Sport Pet 50cl | E13: =IF(D13="","",VLOOKUP(D13,'Product Master'!$B:$G,3,FALSE)) -> Pack | F13: 50 | G13: =IF(D13="","",VLOOKUP(D13,'Product Master'!$B:$G,4,FALSE)) -> 900 | H13: =IF(OR(F13="",G13=""),"",F13*G13) -> 45000
... A16: 46265 | B16: ="PUR"&TEXT(ROW()-1,"0000") -> PUR0015 | C16: Supplier 3 | D16: Malta Guinness 33cl Cans | E16: =IF(D16="","",VLOOKUP(D16,'Product Master'!$B:$G,3,FALSE)) -> Pack | F16: 50 | G16: =IF(D16="","",VLOOKUP(D16,'Product Master'!$B:$G,4,FALSE)) -> 900 | H16: =IF(OR(F16="",G16=""),"",F16*G16) -> 45000
B17: ="PUR"&TEXT(ROW()-1,"0000") -> PUR0016 | E17: =IF(D17="","",VLOOKUP(D17,'Product Master'!$B:$G,3,FALSE)) | G17: =IF(D17="","",VLOOKUP(D17,'Product Master'!$B:$G,4,FALSE)) | H17: =IF(OR(F17="",G17=""),"",F17*G17)
B18: ="PUR"&TEXT(ROW()-1,"0000") -> PUR0017 | E18: =IF(D18="","",VLOOKUP(D18,'Product Master'!$B:$G,3,FALSE)) | G18: =IF(D18="","",VLOOKUP(D18,'Product Master'!$B:$G,4,FALSE)) | H18: =IF(OR(F18="",G18=""),"",F18*G18)
B19: ="PUR"&TEXT(ROW()-1,"0000") -> PUR0018 | E19: =IF(D19="","",VLOOKUP(D19,'Product Master'!$B:$G,3,FALSE)) | G19: =IF(D19="","",VLOOKUP(D19,'Product Master'!$B:$G,4,FALSE)) | H19: =IF(OR(F19="",G19=""),"",F19*G19)
B20: ="PUR"&TEXT(ROW()-1,"0000") -> PUR0019 | E20: =IF(D20="","",VLOOKUP(D20,'Product Master'!$B:$G,3,FALSE)) | G20: =IF(D20="","",VLOOKUP(D20,'Product Master'!$B:$G,4,FALSE)) | H20: =IF(OR(F20="",G20=""),"",F20*G20)
B21: ="PUR"&TEXT(ROW()-1,"0000") -> PUR0020 | E21: =IF(D21="","",VLOOKUP(D21,'Product Master'!$B:$G,3,FALSE)) | G21: =IF(D21="","",VLOOKUP(D21,'Product Master'!$B:$G,4,FALSE)) | H21: =IF(OR(F21="",G21=""),"",F21*G21)
B22: ="PUR"&TEXT(ROW()-1,"0000") -> PUR0021 | E22: =IF(D22="","",VLOOKUP(D22,'Product Master'!$B:$G,3,FALSE)) | G22: =IF(D22="","",VLOOKUP(D22,'Product Master'!$B:$G,4,FALSE)) | H22: =IF(OR(F22="",G22=""),"",F22*G22)
B23: ="PUR"&TEXT(ROW()-1,"0000") -> PUR0022 | E23: =IF(D23="","",VLOOKUP(D23,'Product Master'!$B:$G,3,FALSE)) | G23: =IF(D23="","",VLOOKUP(D23,'Product Master'!$B:$G,4,FALSE)) | H23: =IF(OR(F23="",G23=""),"",F23*G23)
B24: ="PUR"&TEXT(ROW()-1,"0000") -> PUR0023 | E24: =IF(D24="","",VLOOKUP(D24,'Product Master'!$B:$G,3,FALSE)) | G24: =IF(D24="","",VLOOKUP(D24,'Product Master'!$B:$G,4,FALSE)) | H24: =IF(OR(F24="",G24=""),"",F24*G24)
B25: ="PUR"&TEXT(ROW()-1,"0000") -> PUR0024 | E25: =IF(D25="","",VLOOKUP(D25,'Product Master'!$B:$G,3,FALSE)) | G25: =IF(D25="","",VLOOKUP(D25,'Product Master'!$B:$G,4,FALSE)) | H25: =IF(OR(F25="",G25=""),"",F25*G25)
B26: ="PUR"&TEXT(ROW()-1,"0000") -> PUR0025 | E26: =IF(D26="","",VLOOKUP(D26,'Product Master'!$B:$G,3,FALSE)) | G26: =IF(D26="","",VLOOKUP(D26,'Product Master'!$B:$G,4,FALSE)) | H26: =IF(OR(F26="",G26=""),"",F26*G26)
B27: ="PUR"&TEXT(ROW()-1,"0000") -> PUR0026 | E27: =IF(D27="","",VLOOKUP(D27,'Product Master'!$B:$G,3,FALSE)) | G27: =IF(D27="","",VLOOKUP(D27,'Product Master'!$B:$G,4,FALSE)) | H27: =IF(OR(F27="",G27=""),"",F27*G27)
B28: ="PUR"&TEXT(ROW()-1,"0000") -> PUR0027 | E28: =IF(D28="","",VLOOKUP(D28,'Product Master'!$B:$G,3,FALSE)) | G28: =IF(D28="","",VLOOKUP(D28,'Product Master'!$B:$G,4,FALSE)) | H28: =IF(OR(F28="",G28=""),"",F28*G28)
... B502: ="PUR"&TEXT(ROW()-1,"0000") -> PUR0501 | E502: =IF(D502="","",VLOOKUP(D502,'Product Master'!$B:$G,3,FALSE)) | G502: =IF(D502="","",VLOOKUP(D502,'Product Master'!$B:$G,4,FALSE)) | H502: =IF(OR(F502="",G502=""),"",F502*G502)

Sheet Inventory
A1: Product ID | B1: Product Name | C1: Category | D1: Unit | E1: Opening Stock | F1: Total Purchased | G1: Customer Returned | H1: Total Sold | I1: Staff Consumption | J1: Damaged | K1: Expired | L1: Supplier Returned | M1: Closing Stock | N1: Cost Price | O1: Selling Price | P1: Reorder Level | Q1: Inventory Value | R1: Stock Status
A2: P0001 | B2: Beef | C2: =IF(B2="","",VLOOKUP(B2,'Product Master'!$B:$G,2,FALSE)) -> Food | D2: =IF(B2="","",VLOOKUP(B2,'Product Master'!$B:$G,3,FALSE)) -> Piece | E2: 50 | F2: =SUMIF('Stock Purchase'!$D:$D,B2,'Stock Purchase'!$F:$F) -> 50 | G2: =SUMIFS('Stock Adjustment'!$E:$E,'Stock Adjustment'!$B:$B,$A2,'Stock Adjustment'!$D:$D,"Customer Returned") -> 0 | H2: =SUMIF('Daily Sales Entry'!$D:$D,B2,'Daily Sales Entry'!$G:$G) -> 16 | I2: =SUMIFS('Stock Adjustment'!$E:$E,'Stock Adjustment'!$B:$B,$A2,'Stock Adjustment'!$D:$D,"Staff Consumption") -> 0 | J2: =SUMIFS('Stock Adjustment'!$E:$E,'Stock Adjustment'!$B:$B,$A2,'Stock Adjustment'!$D:$D,"Damaged") -> 15 | K2: =SUMIFS('Stock Adjustment'!$E:$E,'Stock Adjustment'!$B:$B,$A2,'Stock Adjustment'!$D:$D,"Expired") -> 0 | L2: =SUMIFS('Stock Adjustment'!$E:$E,'Stock Adjustment'!$B:$B,$A2,'Stock Adjustment'!$D:$D,"Supplier Returned") -> 0 | M2: =Table4[[#This Row],[Opening Stock]]+Table4[[#This Row],[Total Purchased]]+Table4[[#This Row],[Customer Returned]]-Table4[[#This Row],[Total Sold]]-Table4[[#This Row],[Damaged]]-Table4[[#This Row],[Expired]]-Table4[[#This Row],[Supplier Returned]]-Table4[[#This Row],[Staff Consumption]] -> 69 | N2: =IF(B2="","",VLOOKUP(B2,'Product Master'!$B:$G,4,FALSE)) -> 700 | O2: =IF(B2="","",VLOOKUP(B2,'Product Master'!$B:$G,5,FALSE)) -> 1000 | P2: =IF(B2="","",VLOOKUP(B2,'Product Master'!$B:$I,7,FALSE)) -> 20 | Q2: =IFERROR(Table4[[#This Row],[Closing Stock]]*Table4[[#This Row],[Cost Price]],0) -> 48300 | R2: =IF(B2="","",IF(M2=0,"Out of Stock",IF(M2<=10,"Low Stock","In Stock"))) -> In Stock
A3: P0002 | B3: Shaki | C3: =IF(B3="","",VLOOKUP(B3,'Product Master'!$B:$G,2,FALSE)) -> Food | D3: =IF(B3="","",VLOOKUP(B3,'Product Master'!$B:$G,3,FALSE)) -> Piece | F3: =SUMIF('Stock Purchase'!$D:$D,B3,'Stock Purchase'!$F:$F) -> 50 | G3: =SUMIFS('Stock Adjustment'!$E:$E,'Stock Adjustment'!$B:$B,$A3,'Stock Adjustment'!$D:$D,"Customer Returned") -> 0 | H3: =SUMIF('Daily Sales Entry'!$D:$D,B3,'Daily Sales Entry'!$G:$G) -> 27 | I3: =SUMIFS('Stock Adjustment'!$E:$E,'Stock Adjustment'!$B:$B,$A3,'Stock Adjustment'!$D:$D,"Staff Consumption") -> 2 | J3: =SUMIFS('Stock Adjustment'!$E:$E,'Stock Adjustment'!$B:$B,$A3,'Stock Adjustment'!$D:$D,"Damaged") -> 0 | K3: =SUMIFS('Stock Adjustment'!$E:$E,'Stock Adjustment'!$B:$B,$A3,'Stock Adjustment'!$D:$D,"Expired") -> 0 | L3: =SUMIFS('Stock Adjustment'!$E:$E,'Stock Adjustment'!$B:$B,$A3,'Stock Adjustment'!$D:$D,"Supplier Returned") -> 0 | M3: =Table4[[#This Row],[Opening Stock]]+Table4[[#This Row],[Total Purchased]]+Table4[[#This Row],[Customer Returned]]-Table4[[#This Row],[Total Sold]]-Table4[[#This Row],[Damaged]]-Table4[[#This Row],[Expired]]-Table4[[#This Row],[Supplier Returned]]-Table4[[#This Row],[Staff Consumption]] -> 21 | N3: =IF(B3="","",VLOOKUP(B3,'Product Master'!$B:$G,4,FALSE)) -> 900 | O3: =IF(B3="","",VLOOKUP(B3,'Product Master'!$B:$G,5,FALSE)) -> 1200 | P3: =IF(B3="","",VLOOKUP(B3,'Product Master'!$B:$I,7,FALSE)) -> 20 | Q3: =IFERROR(Table4[[#This Row],[Closing Stock]]*Table4[[#This Row],[Cost Price]],0) -> 18900 | R3: =IF(B3="","",IF(M3=0,"Out of Stock",IF(M3<=10,"Low Stock","In Stock"))) -> In Stock
A4: P0003 | B4: Cow leg | C4: =IF(B4="","",VLOOKUP(B4,'Product Master'!$B:$G,2,FALSE)) -> Food | D4: =IF(B4="","",VLOOKUP(B4,'Product Master'!$B:$G,3,FALSE)) -> Piece | F4: =SUMIF('Stock Purchase'!$D:$D,B4,'Stock Purchase'!$F:$F) -> 50 | G4: =SUMIFS('Stock Adjustment'!$E:$E,'Stock Adjustment'!$B:$B,$A4,'Stock Adjustment'!$D:$D,"Customer Returned") -> 0 | H4: =SUMIF('Daily Sales Entry'!$D:$D,B4,'Daily Sales Entry'!$G:$G) -> 8 | I4: =SUMIFS('Stock Adjustment'!$E:$E,'Stock Adjustment'!$B:$B,$A4,'Stock Adjustment'!$D:$D,"Staff Consumption") -> 0 | J4: =SUMIFS('Stock Adjustment'!$E:$E,'Stock Adjustment'!$B:$B,$A4,'Stock Adjustment'!$D:$D,"Damaged") -> 0 | K4: =SUMIFS('Stock Adjustment'!$E:$E,'Stock Adjustment'!$B:$B,$A4,'Stock Adjustment'!$D:$D,"Expired") -> 0 | L4: =SUMIFS('Stock Adjustment'!$E:$E,'Stock Adjustment'!$B:$B,$A4,'Stock Adjustment'!$D:$D,"Supplier Returned") -> 0 | M4: =Table4[[#This Row],[Opening Stock]]+Table4[[#This Row],[Total Purchased]]+Table4[[#This Row],[Customer Returned]]-Table4[[#This Row],[Total Sold]]-Table4[[#This Row],[Damaged]]-Table4[[#This Row],[Expired]]-Table4[[#This Row],[Supplier Returned]]-Table4[[#This Row],[Staff Consumption]] -> 42 | N4: =IF(B4="","",VLOOKUP(B4,'Product Master'!$B:$G,4,FALSE)) -> 1200 | O4: =IF(B4="","",VLOOKUP(B4,'Product Master'!$B:$G,5,FALSE)) -> 1500 | P4: =IF(B4="","",VLOOKUP(B4,'Product Master'!$B:$I,7,FALSE)) -> 20 | Q4: =IFERROR(Table4[[#This Row],[Closing Stock]]*Table4[[#This Row],[Cost Price]],0) -> 50400 | R4: =IF(B4="","",IF(M4=0,"Out of Stock",IF(M4<=10,"Low Stock","In Stock"))) -> In Stock
A5: P0004 | B5: Semovita | C5: =IF(B5="","",VLOOKUP(B5,'Product Master'!$B:$G,2,FALSE)) -> Food | D5: =IF(B5="","",VLOOKUP(B5,'Product Master'!$B:$G,3,FALSE)) -> Piece | F5: =SUMIF('Stock Purchase'!$D:$D,B5,'Stock Purchase'!$F:$F) -> 50 | G5: =SUMIFS('Stock Adjustment'!$E:$E,'Stock Adjustment'!$B:$B,$A5,'Stock Adjustment'!$D:$D,"Customer Returned") -> 0 | H5: =SUMIF('Daily Sales Entry'!$D:$D,B5,'Daily Sales Entry'!$G:$G) -> 7 | I5: =SUMIFS('Stock Adjustment'!$E:$E,'Stock Adjustment'!$B:$B,$A5,'Stock Adjustment'!$D:$D,"Staff Consumption") -> 0 | J5: =SUMIFS('Stock Adjustment'!$E:$E,'Stock Adjustment'!$B:$B,$A5,'Stock Adjustment'!$D:$D,"Damaged") -> 0 | K5: =SUMIFS('Stock Adjustment'!$E:$E,'Stock Adjustment'!$B:$B,$A5,'Stock Adjustment'!$D:$D,"Expired") -> 0 | L5: =SUMIFS('Stock Adjustment'!$E:$E,'Stock Adjustment'!$B:$B,$A5,'Stock Adjustment'!$D:$D,"Supplier Returned") -> 0 | M5: =Table4[[#This Row],[Opening Stock]]+Table4[[#This Row],[Total Purchased]]+Table4[[#This Row],[Customer Returned]]-Table4[[#This Row],[Total Sold]]-Table4[[#This Row],[Damaged]]-Table4[[#This Row],[Expired]]-Table4[[#This Row],[Supplier Returned]]-Table4[[#This Row],[Staff Consumption]] -> 43 | N5: =IF(B5="","",VLOOKUP(B5,'Product Master'!$B:$G,4,FALSE)) -> 400 | O5: =IF(B5="","",VLOOKUP(B5,'Product Master'!$B:$G,5,FALSE)) -> 700 | P5: =IF(B5="","",VLOOKUP(B5,'Product Master'!$B:$I,7,FALSE)) -> 20 | Q5: =IFERROR(Table4[[#This Row],[Closing Stock]]*Table4[[#This Row],[Cost Price]],0) -> 17200 | R5: =IF(B5="","",IF(M5=0,"Out of Stock",IF(M5<=10,"Low Stock","In Stock"))) -> In Stock
